{
  "timestamp": "2025-07-20T10:04:30.572545",
  "version": "CHNeoWave v1.1.0-beta",
  "total_tests": 3,
  "passed": 0,
  "failed": 3,
  "errors": 0,
  "timeouts": 0,
  "total_duration": 28.88593077659607,
  "results": {
    "test_launch_gui.py": {
      "status": "failed",
      "duration": 8.006212949752808,
      "output": "============================= test session starts =============================\ncollecting ... collected 0 items / 1 error\n\n=================================== ERRORS ====================================\n_______________ ERROR collecting tests_smoke/test_launch_gui.py _______________\nImportError while importing test module 'C:\\Users\\LEM\\Desktop\\chneowave\\tests_smoke\\test_launch_gui.py'.\nHint: make sure your test modules/packages have valid Python names.\nTraceback:\n..\\..\\AppData\\Local\\Programs\\Python\\Python311\\Lib\\importlib\\__init__.py:126: in import_module\n    return _bootstrap._gcd_import(name[level:], package, level)\n           ^^^^^^^^^^^^^^^^^^^^^^^^^^^^^^^^^^^^^^^^^^^^^^^^^^^^\ntests_smoke\\test_launch_gui.py:17: in <module>\n    from hrneowave.gui.main_window import CHNeoWaveMainWindow\nsrc\\hrneowave\\gui\\main_window.py:17: in <module>\n    from ..controllers.acquisition_controller import AcquisitionController\nE   ModuleNotFoundError: No module named 'hrneowave.controllers.acquisition_controller'\n=========================== short test summary info ===========================\nERROR tests_smoke/test_launch_gui.py\n!!!!!!!!!!!!!!!!!!! Interrupted: 1 error during collection !!!!!!!!!!!!!!!!!!!!\n============================== 1 error in 2.69s ===============================\n",
      "error": ""
    },
    "test_export_hdf5.py": {
      "status": "failed",
      "duration": 2.8654801845550537,
      "output": "============================= test session starts =============================\ncollecting ... collected 0 items / 1 error\n\n=================================== ERRORS ====================================\n______________ ERROR collecting tests_smoke/test_export_hdf5.py _______________\nImportError while importing test module 'C:\\Users\\LEM\\Desktop\\chneowave\\tests_smoke\\test_export_hdf5.py'.\nHint: make sure your test modules/packages have valid Python names.\nTraceback:\n..\\..\\AppData\\Local\\Programs\\Python\\Python311\\Lib\\importlib\\__init__.py:126: in import_module\n    return _bootstrap._gcd_import(name[level:], package, level)\n           ^^^^^^^^^^^^^^^^^^^^^^^^^^^^^^^^^^^^^^^^^^^^^^^^^^^^\ntests_smoke\\test_export_hdf5.py:24: in <module>\n    from hrneowave.hw.demo_backend import DemoBackend\nE   ModuleNotFoundError: No module named 'hrneowave.hw.demo_backend'\n=========================== short test summary info ===========================\nERROR tests_smoke/test_export_hdf5.py\n!!!!!!!!!!!!!!!!!!! Interrupted: 1 error during collection !!!!!!!!!!!!!!!!!!!!\n============================== 1 error in 2.09s ===============================\n",
      "error": ""
    },
    "test_calib_pdf.py": {
      "status": "failed",
      "duration": 18.014237642288208,
      "output": "============================= test session starts =============================\ncollecting ... collected 6 items\n\ntests_smoke/test_calib_pdf.py::TestCalibPDF::test_pdf_generator_basic FAILED [ 16%]\ntests_smoke/test_calib_pdf.py::TestCalibPDF::test_pdf_content_verification FAILED [ 33%]\ntests_smoke/test_calib_pdf.py::TestCalibPDF::test_pdf_with_high_quality_calibration FAILED [ 50%]\ntests_smoke/test_calib_pdf.py::TestCalibPDF::test_pdf_with_multiple_sensors FAILED [ 66%]\ntests_smoke/test_calib_pdf.py::TestCalibPDF::test_pdf_signature_verification FAILED [ 83%]\ntests_smoke/test_calib_pdf.py::TestCalibPDF::test_pdf_error_handling PASSED [100%]\n\n================================== FAILURES ===================================\n____________________ TestCalibPDF.test_pdf_generator_basic ____________________\ntests_smoke\\test_calib_pdf.py:79: in test_pdf_generator_basic\n    generator.generate_certificate(sample_calibration_data, str(output_file))\n    ^^^^^^^^^^^^^^^^^^^^^^^^^^^^^^\nE   AttributeError: 'CalibrationPDFGenerator' object has no attribute 'generate_certificate'\n\nDuring handling of the above exception, another exception occurred:\ntests_smoke\\test_calib_pdf.py:100: in test_pdf_generator_basic\n    pytest.fail(f\"Erreur génération PDF basique: {str(e)}\")\nE   Failed: Erreur génération PDF basique: 'CalibrationPDFGenerator' object has no attribute 'generate_certificate'\n---------------------------- Captured stdout setup ----------------------------\n\\n=== Configuration environnement de test CHNeoWave ===\\nR\\xe9pertoire projet: C:\\\\Users\\\\LEM\\\\Desktop\\\\chneowave\\nR\\xe9pertoire source: C:\\\\Users\\\\LEM\\\\Desktop\\\\chneowave\\\\src\\nPython: 3.11.9 (tags/v3.11.9:de54cf5, Apr  2 2024, 10:12:12) [MSC v.1938 64 bit (AMD64)]\\n\\u2713 PyQt5\\n\\u2713 numpy\\n\\u2713 scipy\\n\\u2713 h5py\\n\\u2713 reportlab\\n\\u2713 pyqtgraph\\n=== Environnement de test pr\\xeat ===\n_________________ TestCalibPDF.test_pdf_content_verification __________________\ntests_smoke\\test_calib_pdf.py:109: in test_pdf_content_verification\n    generator.generate_certificate(sample_calibration_data, str(output_file))\n    ^^^^^^^^^^^^^^^^^^^^^^^^^^^^^^\nE   AttributeError: 'CalibrationPDFGenerator' object has no attribute 'generate_certificate'\n\nDuring handling of the above exception, another exception occurred:\ntests_smoke\\test_calib_pdf.py:137: in test_pdf_content_verification\n    pytest.fail(f\"Erreur vérification contenu PDF: {str(e)}\")\nE   Failed: Erreur vérification contenu PDF: 'CalibrationPDFGenerator' object has no attribute 'generate_certificate'\n_____________ TestCalibPDF.test_pdf_with_high_quality_calibration _____________\ntests_smoke\\test_calib_pdf.py:165: in test_pdf_with_high_quality_calibration\n    generator.generate_certificate(high_quality_data, str(output_file))\n    ^^^^^^^^^^^^^^^^^^^^^^^^^^^^^^\nE   AttributeError: 'CalibrationPDFGenerator' object has no attribute 'generate_certificate'\n\nDuring handling of the above exception, another exception occurred:\ntests_smoke\\test_calib_pdf.py:176: in test_pdf_with_high_quality_calibration\n    pytest.fail(f\"Erreur PDF haute qualité: {str(e)}\")\nE   Failed: Erreur PDF haute qualité: 'CalibrationPDFGenerator' object has no attribute 'generate_certificate'\n_________________ TestCalibPDF.test_pdf_with_multiple_sensors _________________\ntests_smoke\\test_calib_pdf.py:221: in test_pdf_with_multiple_sensors\n    generator.generate_certificate(multi_sensor_data, str(output_file))\n    ^^^^^^^^^^^^^^^^^^^^^^^^^^^^^^\nE   AttributeError: 'CalibrationPDFGenerator' object has no attribute 'generate_certificate'\n\nDuring handling of the above exception, another exception occurred:\ntests_smoke\\test_calib_pdf.py:235: in test_pdf_with_multiple_sensors\n    pytest.fail(f\"Erreur PDF multi-capteurs: {str(e)}\")\nE   Failed: Erreur PDF multi-capteurs: 'CalibrationPDFGenerator' object has no attribute 'generate_certificate'\n________________ TestCalibPDF.test_pdf_signature_verification _________________\ntests_smoke\\test_calib_pdf.py:244: in test_pdf_signature_verification\n    generator.generate_certificate(sample_calibration_data, str(output_file))\n    ^^^^^^^^^^^^^^^^^^^^^^^^^^^^^^\nE   AttributeError: 'CalibrationPDFGenerator' object has no attribute 'generate_certificate'\n\nDuring handling of the above exception, another exception occurred:\ntests_smoke\\test_calib_pdf.py:261: in test_pdf_signature_verification\n    pytest.fail(f\"Erreur vérification signature: {str(e)}\")\nE   Failed: Erreur vérification signature: 'CalibrationPDFGenerator' object has no attribute 'generate_certificate'\n=========================== short test summary info ===========================\nFAILED tests_smoke/test_calib_pdf.py::TestCalibPDF::test_pdf_generator_basic\nFAILED tests_smoke/test_calib_pdf.py::TestCalibPDF::test_pdf_content_verification\nFAILED tests_smoke/test_calib_pdf.py::TestCalibPDF::test_pdf_with_high_quality_calibration\nFAILED tests_smoke/test_calib_pdf.py::TestCalibPDF::test_pdf_with_multiple_sensors\nFAILED tests_smoke/test_calib_pdf.py::TestCalibPDF::test_pdf_signature_verification\n======================== 5 failed, 1 passed in 16.38s =========================\n",
      "error": ""
    }
  }
}